Workbook

Sheet Mode d'emploi
A1: Pointage du personnel
A2: Outil offert par Logia (DWTS) · Un logiciel sur mesure pour votre entreprise ? WhatsApp 062 67 14 45
B4: 1. Paramètres | C4: Écrivez le nom de votre entreprise et l'année.
B5: 2. Employés | C5: Listez vos employés (jusqu'à 30) et, si vous voulez, leur salaire par jour.
B6: 3. Pointage | C6: Chaque jour, ouvrez le mois et choisissez un code dans la case : P, R, A, C ou M.
B7: 4. Totaux | C7: Les présences, absences, taux de présence et salaire dû se calculent seuls.
B8: 5. Bilan annuel | C8: Le total de l'année par employé, sans rien faire.
B10: Codes
B11: P | C11: Présent
B12: R | C12: En retard
B13: A | C13: Absent
B14: C | C14: Congé
B15: M | C15: Malade
B17: Salaire dû = (jours présents + en retard + congés) × salaire par jour. Les absences et jours de maladie ne sont pas payés : modifiez la formule si votre règle est différente.

Sheet Paramètres
A1: Paramètres
A2: Outil offert par Logia (DWTS) · Un logiciel sur mesure pour votre entreprise ? WhatsApp 062 67 14 45
A4: Nom de l'entreprise | B4: Mon entreprise
A5: Année | B5: 2026
A6: Devise | B6: XAF

Sheet Employés
A1: Employés
A2: Outil offert par Logia (DWTS) · Un logiciel sur mesure pour votre entreprise ? WhatsApp 062 67 14 45
A4: ID | B4: Nom et prénom | C4: Poste | D4: Salaire par jour
A5: E001 | B5: Jean Paul | C5: Vendeur | D5: 5000
A6: E002 | B6: Marie Nzé | C6: Caissière | D6: 5000
A7: E003
A8: E004
A9: E005
A10: E006
A11: E007
A12: E008
A13: E009
A14: E010
A15: E011
A16: E012
A17: E013
A18: E014
... A34: E030

Sheet Bilan annuel
A1: ='Paramètres'!$B$4&" · Bilan annuel "&'Paramètres'!$B$5
A2: Outil offert par Logia (DWTS) · Un logiciel sur mesure pour votre entreprise ? WhatsApp 062 67 14 45
A4: ID | B4: Nom | C4: Présent | D4: Retard | E4: Absent | F4: Congé | G4: Malade | H4: Taux de présence | I4: Salaire dû
A5: =IF('Employés'!B5="","",'Employés'!A5) | B5: =IF('Employés'!B5="","",'Employés'!B5) | C5: =IF($B5="","",N('Janvier'!AI7)+N('Février'!AI7)+N('Mars'!AI7)+N('Avril'!AI7)+N('Mai'!AI7)+N('Juin'!AI7)+N('Juillet'!AI7)+N('Août'!AI7)+N('Septembre'!AI7)+N('Octobre'!AI7)+N('Novembre'!AI7)+N('Décembre'!AI7)) | D5: =IF($B5="","",N('Janvier'!AJ7)+N('Février'!AJ7)+N('Mars'!AJ7)+N('Avril'!AJ7)+N('Mai'!AJ7)+N('Juin'!AJ7)+N('Juillet'!AJ7)+N('Août'!AJ7)+N('Septembre'!AJ7)+N('Octobre'!AJ7)+N('Novembre'!AJ7)+N('Décembre'!AJ7)) | E5: =IF($B5="","",N('Janvier'!AK7)+N('Février'!AK7)+N('Mars'!AK7)+N('Avril'!AK7)+N('Mai'!AK7)+N('Juin'!AK7)+N('Juillet'!AK7)+N('Août'!AK7)+N('Septembre'!AK7)+N('Octobre'!AK7)+N('Novembre'!AK7)+N('Décembre'!AK7)) | F5: =IF($B5="","",N('Janvier'!AL7)+N('Février'!AL7)+N('Mars'!AL7)+N('Avril'!AL7)+N('Mai'!AL7)+N('Juin'!AL7)+N('Juillet'!AL7)+N('Août'!AL7)+N('Septembre'!AL7)+N('Octobre'!AL7)+N('Novembre'!AL7)+N('Décembre'!AL7)) | G5: =IF($B5="","",N('Janvier'!AM7)+N('Février'!AM7)+N('Mars'!AM7)+N('Avril'!AM7)+N('Mai'!AM7)+N('Juin'!AM7)+N('Juillet'!AM7)+N('Août'!AM7)+N('Septembre'!AM7)+N('Octobre'!AM7)+N('Novembre'!AM7)+N('Décembre'!AM7)) | H5: =IF($B5="","",IF(C5+D5+E5+G5=0,"",(C5+D5)/(C5+D5+E5+G5))) | I5: =IF($B5="","",N('Janvier'!AO7)+N('Février'!AO7)+N('Mars'!AO7)+N('Avril'!AO7)+N('Mai'!AO7)+N('Juin'!AO7)+N('Juillet'!AO7)+N('Août'!AO7)+N('Septembre'!AO7)+N('Octobre'!AO7)+N('Novembre'!AO7)+N('Décembre'!AO7))
A6: =IF('Employés'!B6="","",'Employés'!A6) | B6: =IF('Employés'!B6="","",'Employés'!B6) | C6: =IF($B6="","",N('Janvier'!AI8)+N('Février'!AI8)+N('Mars'!AI8)+N('Avril'!AI8)+N('Mai'!AI8)+N('Juin'!AI8)+N('Juillet'!AI8)+N('Août'!AI8)+N('Septembre'!AI8)+N('Octobre'!AI8)+N('Novembre'!AI8)+N('Décembre'!AI8)) | D6: =IF($B6="","",N('Janvier'!AJ8)+N('Février'!AJ8)+N('Mars'!AJ8)+N('Avril'!AJ8)+N('Mai'!AJ8)+N('Juin'!AJ8)+N('Juillet'!AJ8)+N('Août'!AJ8)+N('Septembre'!AJ8)+N('Octobre'!AJ8)+N('Novembre'!AJ8)+N('Décembre'!AJ8)) | E6: =IF($B6="","",N('Janvier'!AK8)+N('Février'!AK8)+N('Mars'!AK8)+N('Avril'!AK8)+N('Mai'!AK8)+N('Juin'!AK8)+N('Juillet'!AK8)+N('Août'!AK8)+N('Septembre'!AK8)+N('Octobre'!AK8)+N('Novembre'!AK8)+N('Décembre'!AK8)) | F6: =IF($B6="","",N('Janvier'!AL8)+N('Février'!AL8)+N('Mars'!AL8)+N('Avril'!AL8)+N('Mai'!AL8)+N('Juin'!AL8)+N('Juillet'!AL8)+N('Août'!AL8)+N('Septembre'!AL8)+N('Octobre'!AL8)+N('Novembre'!AL8)+N('Décembre'!AL8)) | G6: =IF($B6="","",N('Janvier'!AM8)+N('Février'!AM8)+N('Mars'!AM8)+N('Avril'!AM8)+N('Mai'!AM8)+N('Juin'!AM8)+N('Juillet'!AM8)+N('Août'!AM8)+N('Septembre'!AM8)+N('Octobre'!AM8)+N('Novembre'!AM8)+N('Décembre'!AM8)) | H6: =IF($B6="","",IF(C6+D6+E6+G6=0,"",(C6+D6)/(C6+D6+E6+G6))) | I6: =IF($B6="","",N('Janvier'!AO8)+N('Février'!AO8)+N('Mars'!AO8)+N('Avril'!AO8)+N('Mai'!AO8)+N('Juin'!AO8)+N('Juillet'!AO8)+N('Août'!AO8)+N('Septembre'!AO8)+N('Octobre'!AO8)+N('Novembre'!AO8)+N('Décembre'!AO8))
A7: =IF('Employés'!B7="","",'Employés'!A7) | B7: =IF('Employés'!B7="","",'Employés'!B7) | C7: =IF($B7="","",N('Janvier'!AI9)+N('Février'!AI9)+N('Mars'!AI9)+N('Avril'!AI9)+N('Mai'!AI9)+N('Juin'!AI9)+N('Juillet'!AI9)+N('Août'!AI9)+N('Septembre'!AI9)+N('Octobre'!AI9)+N('Novembre'!AI9)+N('Décembre'!AI9)) | D7: =IF($B7="","",N('Janvier'!AJ9)+N('Février'!AJ9)+N('Mars'!AJ9)+N('Avril'!AJ9)+N('Mai'!AJ9)+N('Juin'!AJ9)+N('Juillet'!AJ9)+N('Août'!AJ9)+N('Septembre'!AJ9)+N('Octobre'!AJ9)+N('Novembre'!AJ9)+N('Décembre'!AJ9)) | E7: =IF($B7="","",N('Janvier'!AK9)+N('Février'!AK9)+N('Mars'!AK9)+N('Avril'!AK9)+N('Mai'!AK9)+N('Juin'!AK9)+N('Juillet'!AK9)+N('Août'!AK9)+N('Septembre'!AK9)+N('Octobre'!AK9)+N('Novembre'!AK9)+N('Décembre'!AK9)) | F7: =IF($B7="","",N('Janvier'!AL9)+N('Février'!AL9)+N('Mars'!AL9)+N('Avril'!AL9)+N('Mai'!AL9)+N('Juin'!AL9)+N('Juillet'!AL9)+N('Août'!AL9)+N('Septembre'!AL9)+N('Octobre'!AL9)+N('Novembre'!AL9)+N('Décembre'!AL9)) | G7: =IF($B7="","",N('Janvier'!AM9)+N('Février'!AM9)+N('Mars'!AM9)+N('Avril'!AM9)+N('Mai'!AM9)+N('Juin'!AM9)+N('Juillet'!AM9)+N('Août'!AM9)+N('Septembre'!AM9)+N('Octobre'!AM9)+N('Novembre'!AM9)+N('Décembre'!AM9)) | H7: =IF($B7="","",IF(C7+D7+E7+G7=0,"",(C7+D7)/(C7+D7+E7+G7))) | I7: =IF($B7="","",N('Janvier'!AO9)+N('Février'!AO9)+N('Mars'!AO9)+N('Avril'!AO9)+N('Mai'!AO9)+N('Juin'!AO9)+N('Juillet'!AO9)+N('Août'!AO9)+N('Septembre'!AO9)+N('Octobre'!AO9)+N('Novembre'!AO9)+N('Décembre'!AO9))
A8: =IF('Employés'!B8="","",'Employés'!A8) | B8: =IF('Employés'!B8="","",'Employés'!B8) | C8: =IF($B8="","",N('Janvier'!AI10)+N('Février'!AI10)+N('Mars'!AI10)+N('Avril'!AI10)+N('Mai'!AI10)+N('Juin'!AI10)+N('Juillet'!AI10)+N('Août'!AI10)+N('Septembre'!AI10)+N('Octobre'!AI10)+N('Novembre'!AI10)+N('Décembre'!AI10)) | D8: =IF($B8="","",N('Janvier'!AJ10)+N('Février'!AJ10)+N('Mars'!AJ10)+N('Avril'!AJ10)+N('Mai'!AJ10)+N('Juin'!AJ10)+N('Juillet'!AJ10)+N('Août'!AJ10)+N('Septembre'!AJ10)+N('Octobre'!AJ10)+N('Novembre'!AJ10)+N('Décembre'!AJ10)) | E8: =IF($B8="","",N('Janvier'!AK10)+N('Février'!AK10)+N('Mars'!AK10)+N('Avril'!AK10)+N('Mai'!AK10)+N('Juin'!AK10)+N('Juillet'!AK10)+N('Août'!AK10)+N('Septembre'!AK10)+N('Octobre'!AK10)+N('Novembre'!AK10)+N('Décembre'!AK10)) | F8: =IF($B8="","",N('Janvier'!AL10)+N('Février'!AL10)+N('Mars'!AL10)+N('Avril'!AL10)+N('Mai'!AL10)+N('Juin'!AL10)+N('Juillet'!AL10)+N('Août'!AL10)+N('Septembre'!AL10)+N('Octobre'!AL10)+N('Novembre'!AL10)+N('Décembre'!AL10)) | G8: =IF($B8="","",N('Janvier'!AM10)+N('Février'!AM10)+N('Mars'!AM10)+N('Avril'!AM10)+N('Mai'!AM10)+N('Juin'!AM10)+N('Juillet'!AM10)+N('Août'!AM10)+N('Septembre'!AM10)+N('Octobre'!AM10)+N('Novembre'!AM10)+N('Décembre'!AM10)) | H8: =IF($B8="","",IF(C8+D8+E8+G8=0,"",(C8+D8)/(C8+D8+E8+G8))) | I8: =IF($B8="","",N('Janvier'!AO10)+N('Février'!AO10)+N('Mars'!AO10)+N('Avril'!AO10)+N('Mai'!AO10)+N('Juin'!AO10)+N('Juillet'!AO10)+N('Août'!AO10)+N('Septembre'!AO10)+N('Octobre'!AO10)+N('Novembre'!AO10)+N('Décembre'!AO10))
A9: =IF('Employés'!B9="","",'Employés'!A9) | B9: =IF('Employés'!B9="","",'Employés'!B9) | C9: =IF($B9="","",N('Janvier'!AI11)+N('Février'!AI11)+N('Mars'!AI11)+N('Avril'!AI11)+N('Mai'!AI11)+N('Juin'!AI11)+N('Juillet'!AI11)+N('Août'!AI11)+N('Septembre'!AI11)+N('Octobre'!AI11)+N('Novembre'!AI11)+N('Décembre'!AI11)) | D9: =IF($B9="","",N('Janvier'!AJ11)+N('Février'!AJ11)+N('Mars'!AJ11)+N('Avril'!AJ11)+N('Mai'!AJ11)+N('Juin'!AJ11)+N('Juillet'!AJ11)+N('Août'!AJ11)+N('Septembre'!AJ11)+N('Octobre'!AJ11)+N('Novembre'!AJ11)+N('Décembre'!AJ11)) | E9: =IF($B9="","",N('Janvier'!AK11)+N('Février'!AK11)+N('Mars'!AK11)+N('Avril'!AK11)+N('Mai'!AK11)+N('Juin'!AK11)+N('Juillet'!AK11)+N('Août'!AK11)+N('Septembre'!AK11)+N('Octobre'!AK11)+N('Novembre'!AK11)+N('Décembre'!AK11)) | F9: =IF($B9="","",N('Janvier'!AL11)+N('Février'!AL11)+N('Mars'!AL11)+N('Avril'!AL11)+N('Mai'!AL11)+N('Juin'!AL11)+N('Juillet'!AL11)+N('Août'!AL11)+N('Septembre'!AL11)+N('Octobre'!AL11)+N('Novembre'!AL11)+N('Décembre'!AL11)) | G9: =IF($B9="","",N('Janvier'!AM11)+N('Février'!AM11)+N('Mars'!AM11)+N('Avril'!AM11)+N('Mai'!AM11)+N('Juin'!AM11)+N('Juillet'!AM11)+N('Août'!AM11)+N('Septembre'!AM11)+N('Octobre'!AM11)+N('Novembre'!AM11)+N('Décembre'!AM11)) | H9: =IF($B9="","",IF(C9+D9+E9+G9=0,"",(C9+D9)/(C9+D9+E9+G9))) | I9: =IF($B9="","",N('Janvier'!AO11)+N('Février'!AO11)+N('Mars'!AO11)+N('Avril'!AO11)+N('Mai'!AO11)+N('Juin'!AO11)+N('Juillet'!AO11)+N('Août'!AO11)+N('Septembre'!AO11)+N('Octobre'!AO11)+N('Novembre'!AO11)+N('Décembre'!AO11))
A10: =IF('Employés'!B10="","",'Employés'!A10) | B10: =IF('Employés'!B10="","",'Employés'!B10) | C10: =IF($B10="","",N('Janvier'!AI12)+N('Février'!AI12)+N('Mars'!AI12)+N('Avril'!AI12)+N('Mai'!AI12)+N('Juin'!AI12)+N('Juillet'!AI12)+N('Août'!AI12)+N('Septembre'!AI12)+N('Octobre'!AI12)+N('Novembre'!AI12)+N('Décembre'!AI12)) | D10: =IF($B10="","",N('Janvier'!AJ12)+N('Février'!AJ12)+N('Mars'!AJ12)+N('Avril'!AJ12)+N('Mai'!AJ12)+N('Juin'!AJ12)+N('Juillet'!AJ12)+N('Août'!AJ12)+N('Septembre'!AJ12)+N('Octobre'!AJ12)+N('Novembre'!AJ12)+N('Décembre'!AJ12)) | E10: =IF($B10="","",N('Janvier'!AK12)+N('Février'!AK12)+N('Mars'!AK12)+N('Avril'!AK12)+N('Mai'!AK12)+N('Juin'!AK12)+N('Juillet'!AK12)+N('Août'!AK12)+N('Septembre'!AK12)+N('Octobre'!AK12)+N('Novembre'!AK12)+N('Décembre'!AK12)) | F10: =IF($B10="","",N('Janvier'!AL12)+N('Février'!AL12)+N('Mars'!AL12)+N('Avril'!AL12)+N('Mai'!AL12)+N('Juin'!AL12)+N('Juillet'!AL12)+N('Août'!AL12)+N('Septembre'!AL12)+N('Octobre'!AL12)+N('Novembre'!AL12)+N('Décembre'!AL12)) | G10: =IF($B10="","",N('Janvier'!AM12)+N('Février'!AM12)+N('Mars'!AM12)+N('Avril'!AM12)+N('Mai'!AM12)+N('Juin'!AM12)+N('Juillet'!AM12)+N('Août'!AM12)+N('Septembre'!AM12)+N('Octobre'!AM12)+N('Novembre'!AM12)+N('Décembre'!AM12)) | H10: =IF($B10="","",IF(C10+D10+E10+G10=0,"",(C10+D10)/(C10+D10+E10+G10))) | I10: =IF($B10="","",N('Janvier'!AO12)+N('Février'!AO12)+N('Mars'!AO12)+N('Avril'!AO12)+N('Mai'!AO12)+N('Juin'!AO12)+N('Juillet'!AO12)+N('Août'!AO12)+N('Septembre'!AO12)+N('Octobre'!AO12)+N('Novembre'!AO12)+N('Décembre'!AO12))
A11: =IF('Employés'!B11="","",'Employés'!A11) | B11: =IF('Employés'!B11="","",'Employés'!B11) | C11: =IF($B11="","",N('Janvier'!AI13)+N('Février'!AI13)+N('Mars'!AI13)+N('Avril'!AI13)+N('Mai'!AI13)+N('Juin'!AI13)+N('Juillet'!AI13)+N('Août'!AI13)+N('Septembre'!AI13)+N('Octobre'!AI13)+N('Novembre'!AI13)+N('Décembre'!AI13)) | D11: =IF($B11="","",N('Janvier'!AJ13)+N('Février'!AJ13)+N('Mars'!AJ13)+N('Avril'!AJ13)+N('Mai'!AJ13)+N('Juin'!AJ13)+N('Juillet'!AJ13)+N('Août'!AJ13)+N('Septembre'!AJ13)+N('Octobre'!AJ13)+N('Novembre'!AJ13)+N('Décembre'!AJ13)) | E11: =IF($B11="","",N('Janvier'!AK13)+N('Février'!AK13)+N('Mars'!AK13)+N('Avril'!AK13)+N('Mai'!AK13)+N('Juin'!AK13)+N('Juillet'!AK13)+N('Août'!AK13)+N('Septembre'!AK13)+N('Octobre'!AK13)+N('Novembre'!AK13)+N('Décembre'!AK13)) | F11: =IF($B11="","",N('Janvier'!AL13)+N('Février'!AL13)+N('Mars'!AL13)+N('Avril'!AL13)+N('Mai'!AL13)+N('Juin'!AL13)+N('Juillet'!AL13)+N('Août'!AL13)+N('Septembre'!AL13)+N('Octobre'!AL13)+N('Novembre'!AL13)+N('Décembre'!AL13)) | G11: =IF($B11="","",N('Janvier'!AM13)+N('Février'!AM13)+N('Mars'!AM13)+N('Avril'!AM13)+N('Mai'!AM13)+N('Juin'!AM13)+N('Juillet'!AM13)+N('Août'!AM13)+N('Septembre'!AM13)+N('Octobre'!AM13)+N('Novembre'!AM13)+N('Décembre'!AM13)) | H11: =IF($B11="","",IF(C11+D11+E11+G11=0,"",(C11+D11)/(C11+D11+E11+G11))) | I11: =IF($B11="","",N('Janvier'!AO13)+N('Février'!AO13)+N('Mars'!AO13)+N('Avril'!AO13)+N('Mai'!AO13)+N('Juin'!AO13)+N('Juillet'!AO13)+N('Août'!AO13)+N('Septembre'!AO13)+N('Octobre'!AO13)+N('Novembre'!AO13)+N('Décembre'!AO13))
A12: =IF('Employés'!B12="","",'Employés'!A12) | B12: =IF('Employés'!B12="","",'Employés'!B12) | C12: =IF($B12="","",N('Janvier'!AI14)+N('Février'!AI14)+N('Mars'!AI14)+N('Avril'!AI14)+N('Mai'!AI14)+N('Juin'!AI14)+N('Juillet'!AI14)+N('Août'!AI14)+N('Septembre'!AI14)+N('Octobre'!AI14)+N('Novembre'!AI14)+N('Décembre'!AI14)) | D12: =IF($B12="","",N('Janvier'!AJ14)+N('Février'!AJ14)+N('Mars'!AJ14)+N('Avril'!AJ14)+N('Mai'!AJ14)+N('Juin'!AJ14)+N('Juillet'!AJ14)+N('Août'!AJ14)+N('Septembre'!AJ14)+N('Octobre'!AJ14)+N('Novembre'!AJ14)+N('Décembre'!AJ14)) | E12: =IF($B12="","",N('Janvier'!AK14)+N('Février'!AK14)+N('Mars'!AK14)+N('Avril'!AK14)+N('Mai'!AK14)+N('Juin'!AK14)+N('Juillet'!AK14)+N('Août'!AK14)+N('Septembre'!AK14)+N('Octobre'!AK14)+N('Novembre'!AK14)+N('Décembre'!AK14)) | F12: =IF($B12="","",N('Janvier'!AL14)+N('Février'!AL14)+N('Mars'!AL14)+N('Avril'!AL14)+N('Mai'!AL14)+N('Juin'!AL14)+N('Juillet'!AL14)+N('Août'!AL14)+N('Septembre'!AL14)+N('Octobre'!AL14)+N('Novembre'!AL14)+N('Décembre'!AL14)) | G12: =IF($B12="","",N('Janvier'!AM14)+N('Février'!AM14)+N('Mars'!AM14)+N('Avril'!AM14)+N('Mai'!AM14)+N('Juin'!AM14)+N('Juillet'!AM14)+N('Août'!AM14)+N('Septembre'!AM14)+N('Octobre'!AM14)+N('Novembre'!AM14)+N('Décembre'!AM14)) | H12: =IF($B12="","",IF(C12+D12+E12+G12=0,"",(C12+D12)/(C12+D12+E12+G12))) | I12: =IF($B12="","",N('Janvier'!AO14)+N('Février'!AO14)+N('Mars'!AO14)+N('Avril'!AO14)+N('Mai'!AO14)+N('Juin'!AO14)+N('Juillet'!AO14)+N('Août'!AO14)+N('Septembre'!AO14)+N('Octobre'!AO14)+N('Novembre'!AO14)+N('Décembre'!AO14))
A13: =IF('Employés'!B13="","",'Employés'!A13) | B13: =IF('Employés'!B13="","",'Employés'!B13) | C13: =IF($B13="","",N('Janvier'!AI15)+N('Février'!AI15)+N('Mars'!AI15)+N('Avril'!AI15)+N('Mai'!AI15)+N('Juin'!AI15)+N('Juillet'!AI15)+N('Août'!AI15)+N('Septembre'!AI15)+N('Octobre'!AI15)+N('Novembre'!AI15)+N('Décembre'!AI15)) | D13: =IF($B13="","",N('Janvier'!AJ15)+N('Février'!AJ15)+N('Mars'!AJ15)+N('Avril'!AJ15)+N('Mai'!AJ15)+N('Juin'!AJ15)+N('Juillet'!AJ15)+N('Août'!AJ15)+N('Septembre'!AJ15)+N('Octobre'!AJ15)+N('Novembre'!AJ15)+N('Décembre'!AJ15)) | E13: =IF($B13="","",N('Janvier'!AK15)+N('Février'!AK15)+N('Mars'!AK15)+N('Avril'!AK15)+N('Mai'!AK15)+N('Juin'!AK15)+N('Juillet'!AK15)+N('Août'!AK15)+N('Septembre'!AK15)+N('Octobre'!AK15)+N('Novembre'!AK15)+N('Décembre'!AK15)) | F13: =IF($B13="","",N('Janvier'!AL15)+N('Février'!AL15)+N('Mars'!AL15)+N('Avril'!AL15)+N('Mai'!AL15)+N('Juin'!AL15)+N('Juillet'!AL15)+N('Août'!AL15)+N('Septembre'!AL15)+N('Octobre'!AL15)+N('Novembre'!AL15)+N('Décembre'!AL15)) | G13: =IF($B13="","",N('Janvier'!AM15)+N('Février'!AM15)+N('Mars'!AM15)+N('Avril'!AM15)+N('Mai'!AM15)+N('Juin'!AM15)+N('Juillet'!AM15)+N('Août'!AM15)+N('Septembre'!AM15)+N('Octobre'!AM15)+N('Novembre'!AM15)+N('Décembre'!AM15)) | H13: =IF($B13="","",IF(C13+D13+E13+G13=0,"",(C13+D13)/(C13+D13+E13+G13))) | I13: =IF($B13="","",N('Janvier'!AO15)+N('Février'!AO15)+N('Mars'!AO15)+N('Avril'!AO15)+N('Mai'!AO15)+N('Juin'!AO15)+N('Juillet'!AO15)+N('Août'!AO15)+N('Septembre'!AO15)+N('Octobre'!AO15)+N('Novembre'!AO15)+N('Décembre'!AO15))
A14: =IF('Employés'!B14="","",'Employés'!A14) | B14: =IF('Employés'!B14="","",'Employés'!B14) | C14: =IF($B14="","",N('Janvier'!AI16)+N('Février'!AI16)+N('Mars'!AI16)+N('Avril'!AI16)+N('Mai'!AI16)+N('Juin'!AI16)+N('Juillet'!AI16)+N('Août'!AI16)+N('Septembre'!AI16)+N('Octobre'!AI16)+N('Novembre'!AI16)+N('Décembre'!AI16)) | D14: =IF($B14="","",N('Janvier'!AJ16)+N('Février'!AJ16)+N('Mars'!AJ16)+N('Avril'!AJ16)+N('Mai'!AJ16)+N('Juin'!AJ16)+N('Juillet'!AJ16)+N('Août'!AJ16)+N('Septembre'!AJ16)+N('Octobre'!AJ16)+N('Novembre'!AJ16)+N('Décembre'!AJ16)) | E14: =IF($B14="","",N('Janvier'!AK16)+N('Février'!AK16)+N('Mars'!AK16)+N('Avril'!AK16)+N('Mai'!AK16)+N('Juin'!AK16)+N('Juillet'!AK16)+N('Août'!AK16)+N('Septembre'!AK16)+N('Octobre'!AK16)+N('Novembre'!AK16)+N('Décembre'!AK16)) | F14: =IF($B14="","",N('Janvier'!AL16)+N('Février'!AL16)+N('Mars'!AL16)+N('Avril'!AL16)+N('Mai'!AL16)+N('Juin'!AL16)+N('Juillet'!AL16)+N('Août'!AL16)+N('Septembre'!AL16)+N('Octobre'!AL16)+N('Novembre'!AL16)+N('Décembre'!AL16)) | G14: =IF($B14="","",N('Janvier'!AM16)+N('Février'!AM16)+N('Mars'!AM16)+N('Avril'!AM16)+N('Mai'!AM16)+N('Juin'!AM16)+N('Juillet'!AM16)+N('Août'!AM16)+N('Septembre'!AM16)+N('Octobre'!AM16)+N('Novembre'!AM16)+N('Décembre'!AM16)) | H14: =IF($B14="","",IF(C14+D14+E14+G14=0,"",(C14+D14)/(C14+D14+E14+G14))) | I14: =IF($B14="","",N('Janvier'!AO16)+N('Février'!AO16)+N('Mars'!AO16)+N('Avril'!AO16)+N('Mai'!AO16)+N('Juin'!AO16)+N('Juillet'!AO16)+N('Août'!AO16)+N('Septembre'!AO16)+N('Octobre'!AO16)+N('Novembre'!AO16)+N('Décembre'!AO16))
A15: =IF('Employés'!B15="","",'Employés'!A15) | B15: =IF('Employés'!B15="","",'Employés'!B15) | C15: =IF($B15="","",N('Janvier'!AI17)+N('Février'!AI17)+N('Mars'!AI17)+N('Avril'!AI17)+N('Mai'!AI17)+N('Juin'!AI17)+N('Juillet'!AI17)+N('Août'!AI17)+N('Septembre'!AI17)+N('Octobre'!AI17)+N('Novembre'!AI17)+N('Décembre'!AI17)) | D15: =IF($B15="","",N('Janvier'!AJ17)+N('Février'!AJ17)+N('Mars'!AJ17)+N('Avril'!AJ17)+N('Mai'!AJ17)+N('Juin'!AJ17)+N('Juillet'!AJ17)+N('Août'!AJ17)+N('Septembre'!AJ17)+N('Octobre'!AJ17)+N('Novembre'!AJ17)+N('Décembre'!AJ17)) | E15: =IF($B15="","",N('Janvier'!AK17)+N('Février'!AK17)+N('Mars'!AK17)+N('Avril'!AK17)+N('Mai'!AK17)+N('Juin'!AK17)+N('Juillet'!AK17)+N('Août'!AK17)+N('Septembre'!AK17)+N('Octobre'!AK17)+N('Novembre'!AK17)+N('Décembre'!AK17)) | F15: =IF($B15="","",N('Janvier'!AL17)+N('Février'!AL17)+N('Mars'!AL17)+N('Avril'!AL17)+N('Mai'!AL17)+N('Juin'!AL17)+N('Juillet'!AL17)+N('Août'!AL17)+N('Septembre'!AL17)+N('Octobre'!AL17)+N('Novembre'!AL17)+N('Décembre'!AL17)) | G15: =IF($B15="","",N('Janvier'!AM17)+N('Février'!AM17)+N('Mars'!AM17)+N('Avril'!AM17)+N('Mai'!AM17)+N('Juin'!AM17)+N('Juillet'!AM17)+N('Août'!AM17)+N('Septembre'!AM17)+N('Octobre'!AM17)+N('Novembre'!AM17)+N('Décembre'!AM17)) | H15: =IF($B15="","",IF(C15+D15+E15+G15=0,"",(C15+D15)/(C15+D15+E15+G15))) | I15: =IF($B15="","",N('Janvier'!AO17)+N('Février'!AO17)+N('Mars'!AO17)+N('Avril'!AO17)+N('Mai'!AO17)+N('Juin'!AO17)+N('Juillet'!AO17)+N('Août'!AO17)+N('Septembre'!AO17)+N('Octobre'!AO17)+N('Novembre'!AO17)+N('Décembre'!AO17))
A16: =IF('Employés'!B16="","",'Employés'!A16) | B16: =IF('Employés'!B16="","",'Employés'!B16) | C16: =IF($B16="","",N('Janvier'!AI18)+N('Février'!AI18)+N('Mars'!AI18)+N('Avril'!AI18)+N('Mai'!AI18)+N('Juin'!AI18)+N('Juillet'!AI18)+N('Août'!AI18)+N('Septembre'!AI18)+N('Octobre'!AI18)+N('Novembre'!AI18)+N('Décembre'!AI18)) | D16: =IF($B16="","",N('Janvier'!AJ18)+N('Février'!AJ18)+N('Mars'!AJ18)+N('Avril'!AJ18)+N('Mai'!AJ18)+N('Juin'!AJ18)+N('Juillet'!AJ18)+N('Août'!AJ18)+N('Septembre'!AJ18)+N('Octobre'!AJ18)+N('Novembre'!AJ18)+N('Décembre'!AJ18)) | E16: =IF($B16="","",N('Janvier'!AK18)+N('Février'!AK18)+N('Mars'!AK18)+N('Avril'!AK18)+N('Mai'!AK18)+N('Juin'!AK18)+N('Juillet'!AK18)+N('Août'!AK18)+N('Septembre'!AK18)+N('Octobre'!AK18)+N('Novembre'!AK18)+N('Décembre'!AK18)) | F16: =IF($B16="","",N('Janvier'!AL18)+N('Février'!AL18)+N('Mars'!AL18)+N('Avril'!AL18)+N('Mai'!AL18)+N('Juin'!AL18)+N('Juillet'!AL18)+N('Août'!AL18)+N('Septembre'!AL18)+N('Octobre'!AL18)+N('Novembre'!AL18)+N('Décembre'!AL18)) | G16: =IF($B16="","",N('Janvier'!AM18)+N('Février'!AM18)+N('Mars'!AM18)+N('Avril'!AM18)+N('Mai'!AM18)+N('Juin'!AM18)+N('Juillet'!AM18)+N('Août'!AM18)+N('Septembre'!AM18)+N('Octobre'!AM18)+N('Novembre'!AM18)+N('Décembre'!AM18)) | H16: =IF($B16="","",IF(C16+D16+E16+G16=0,"",(C16+D16)/(C16+D16+E16+G16))) | I16: =IF($B16="","",N('Janvier'!AO18)+N('Février'!AO18)+N('Mars'!AO18)+N('Avril'!AO18)+N('Mai'!AO18)+N('Juin'!AO18)+N('Juillet'!AO18)+N('Août'!AO18)+N('Septembre'!AO18)+N('Octobre'!AO18)+N('Novembre'!AO18)+N('Décembre'!AO18))
... A34: =IF('Employés'!B34="","",'Employés'!A34) | B34: =IF('Employés'!B34="","",'Employés'!B34) | C34: =IF($B34="","",N('Janvier'!AI36)+N('Février'!AI36)+N('Mars'!AI36)+N('Avril'!AI36)+N('Mai'!AI36)+N('Juin'!AI36)+N('Juillet'!AI36)+N('Août'!AI36)+N('Septembre'!AI36)+N('Octobre'!AI36)+N('Novembre'!AI36)+N('Décembre'!AI36)) | D34: =IF($B34="","",N('Janvier'!AJ36)+N('Février'!AJ36)+N('Mars'!AJ36)+N('Avril'!AJ36)+N('Mai'!AJ36)+N('Juin'!AJ36)+N('Juillet'!AJ36)+N('Août'!AJ36)+N('Septembre'!AJ36)+N('Octobre'!AJ36)+N('Novembre'!AJ36)+N('Décembre'!AJ36)) | E34: =IF($B34="","",N('Janvier'!AK36)+N('Février'!AK36)+N('Mars'!AK36)+N('Avril'!AK36)+N('Mai'!AK36)+N('Juin'!AK36)+N('Juillet'!AK36)+N('Août'!AK36)+N('Septembre'!AK36)+N('Octobre'!AK36)+N('Novembre'!AK36)+N('Décembre'!AK36)) | F34: =IF($B34="","",N('Janvier'!AL36)+N('Février'!AL36)+N('Mars'!AL36)+N('Avril'!AL36)+N('Mai'!AL36)+N('Juin'!AL36)+N('Juillet'!AL36)+N('Août'!AL36)+N('Septembre'!AL36)+N('Octobre'!AL36)+N('Novembre'!AL36)+N('Décembre'!AL36)) | G34: =IF($B34="","",N('Janvier'!AM36)+N('Février'!AM36)+N('Mars'!AM36)+N('Avril'!AM36)+N('Mai'!AM36)+N('Juin'!AM36)+N('Juillet'!AM36)+N('Août'!AM36)+N('Septembre'!AM36)+N('Octobre'!AM36)+N('Novembre'!AM36)+N('Décembre'!AM36)) | H34: =IF($B34="","",IF(C34+D34+E34+G34=0,"",(C34+D34)/(C34+D34+E34+G34))) | I34: =IF($B34="","",N('Janvier'!AO36)+N('Février'!AO36)+N('Mars'!AO36)+N('Avril'!AO36)+N('Mai'!AO36)+N('Juin'!AO36)+N('Juillet'!AO36)+N('Août'!AO36)+N('Septembre'!AO36)+N('Octobre'!AO36)+N('Novembre'!AO36)+N('Décembre'!AO36))

Sheet Janvier
A1: ='Paramètres'!$B$4&" · Pointage de Janvier "&'Paramètres'!$B$5
A2: Outil offert par Logia (DWTS) · Un logiciel sur mesure pour votre entreprise ? WhatsApp 062 67 14 45
A3: Codes : | D3: P = Présent | I3: R = En retard | N3: A = Absent | S3: C = Congé | X3: M = Malade
A5: ID | B5: Nom | C5: Poste | D5: =IF(MONTH(DATE('Paramètres'!$B$5,1,1))=1,1,"") | E5: =IF(MONTH(DATE('Paramètres'!$B$5,1,2))=1,2,"") | F5: =IF(MONTH(DATE('Paramètres'!$B$5,1,3))=1,3,"") | G5: =IF(MONTH(DATE('Paramètres'!$B$5,1,4))=1,4,"") | H5: =IF(MONTH(DATE('Paramètres'!$B$5,1,5))=1,5,"") | I5: =IF(MONTH(DATE('Paramètres'!$B$5,1,6))=1,6,"") | J5: =IF(MONTH(DATE('Paramètres'!$B$5,1,7))=1,7,"") | K5: =IF(MONTH(DATE('Paramètres'!$B$5,1,8))=1,8,"") | L5: =IF(MONTH(DATE('Paramètres'!$B$5,1,9))=1,9,"") | M5: =IF(MONTH(DATE('Paramètres'!$B$5,1,10))=1,10,"") | N5: =IF(MONTH(DATE('Paramètres'!$B$5,1,11))=1,11,"") | O5: =IF(MONTH(DATE('Paramètres'!$B$5,1,12))=1,12,"") | P5: =IF(MONTH(DATE('Paramètres'!$B$5,1,13))=1,13,"") | Q5: =IF(MONTH(DATE('Paramètres'!$B$5,1,14))=1,14,"") | R5: =IF(MONTH(DATE('Paramètres'!$B$5,1,15))=1,15,"") | S5: =IF(MONTH(DATE('Paramètres'!$B$5,1,16))=1,16,"") | T5: =IF(MONTH(DATE('Paramètres'!$B$5,1,17))=1,17,"") | U5: =IF(MONTH(DATE('Paramètres'!$B$5,1,18))=1,18,"") | V5: =IF(MONTH(DATE('Paramètres'!$B$5,1,19))=1,19,"") | W5: =IF(MONTH(DATE('Paramètres'!$B$5,1,20))=1,20,"") | X5: =IF(MONTH(DATE('Paramètres'!$B$5,1,21))=1,21,"") | Y5: =IF(MONTH(DATE('Paramètres'!$B$5,1,22))=1,22,"") | Z5: =IF(MONTH(DATE('Paramètres'!$B$5,1,23))=1,23,"") | AA5: =IF(MONTH(DATE('Paramètres'!$B$5,1,24))=1,24,"") | AB5: =IF(MONTH(DATE('Paramètres'!$B$5,1,25))=1,25,"") | AC5: =IF(MONTH(DATE('Paramètres'!$B$5,1,26))=1,26,"") | AD5: =IF(MONTH(DATE('Paramètres'!$B$5,1,27))=1,27,"") | AE5: =IF(MONTH(DATE('Paramètres'!$B$5,1,28))=1,28,"") | AF5: =IF(MONTH(DATE('Paramètres'!$B$5,1,29))=1,29,"") | AG5: =IF(MONTH(DATE('Paramètres'!$B$5,1,30))=1,30,"") | AH5: =IF(MONTH(DATE('Paramètres'!$B$5,1,31))=1,31,"") | AI5: Présent | AJ5: Retard | AK5: Absent | AL5: Congé | AM5: Malade | AN5: Taux de présence | AO5: Salaire dû
D6: =IF(D5="","",CHOOSE(WEEKDAY(DATE('Paramètres'!$B$5,1,1),2),"Lun","Mar","Mer","Jeu","Ven","Sam","Dim")) | E6: =IF(E5="","",CHOOSE(WEEKDAY(DATE('Paramètres'!$B$5,1,2),2),"Lun","Mar","Mer","Jeu","Ven","Sam","Dim")) | F6: =IF(F5="","",CHOOSE(WEEKDAY(DATE('Paramètres'!$B$5,1,3),2),"Lun","Mar","Mer","Jeu","Ven","Sam","Dim")) | G6: =IF(G5="","",CHOOSE(WEEKDAY(DATE('Paramètres'!$B$5,1,4),2),"Lun","Mar","Mer","Jeu","Ven","Sam","Dim")) | H6: =IF(H5="","",CHOOSE(WEEKDAY(DATE('Paramètres'!$B$5,1,5),2),"Lun","Mar","Mer","Jeu","Ven","Sam","Dim")) | I6: =IF(I5="","",CHOOSE(WEEKDAY(DATE('Paramètres'!$B$5,1,6),2),"Lun","Mar","Mer","Jeu","Ven","Sam","Dim")) | J6: =IF(J5="","",CHOOSE(WEEKDAY(DATE('Paramètres'!$B$5,1,7),2),"Lun","Mar","Mer","Jeu","Ven","Sam","Dim")) | K6: =IF(K5="","",CHOOSE(WEEKDAY(DATE('Paramètres'!$B$5,1,8),2),"Lun","Mar","Mer","Jeu","Ven","Sam","Dim")) | L6: =IF(L5="","",CHOOSE(WEEKDAY(DATE('Paramètres'!$B$5,1,9),2),"Lun","Mar","Mer","Jeu","Ven","Sam","Dim")) | M6: =IF(M5="","",CHOOSE(WEEKDAY(DATE('Paramètres'!$B$5,1,10),2),"Lun","Mar","Mer","Jeu","Ven","Sam","Dim")) | N6: =IF(N5="","",CHOOSE(WEEKDAY(DATE('Paramètres'!$B$5,1,11),2),"Lun","Mar","Mer","Jeu","Ven","Sam","Dim")) | O6: =IF(O5="","",CHOOSE(WEEKDAY(DATE('Paramètres'!$B$5,1,12),2),"Lun","Mar","Mer","Jeu","Ven","Sam","Dim")) | P6: =IF(P5="","",CHOOSE(WEEKDAY(DATE('Paramètres'!$B$5,1,13),2),"Lun","Mar","Mer","Jeu","Ven","Sam","Dim")) | Q6: =IF(Q5="","",CHOOSE(WEEKDAY(DATE('Paramètres'!$B$5,1,14),2),"Lun","Mar","Mer","Jeu","Ven","Sam","Dim")) | R6: =IF(R5="","",CHOOSE(WEEKDAY(DATE('Paramètres'!$B$5,1,15),2),"Lun","Mar","Mer","Jeu","Ven","Sam","Dim")) | S6: =IF(S5="","",CHOOSE(WEEKDAY(DATE('Paramètres'!$B$5,1,16),2),"Lun","Mar","Mer","Jeu","Ven","Sam","Dim")) | T6: =IF(T5="","",CHOOSE(WEEKDAY(DATE('Paramètres'!$B$5,1,17),2),"Lun","Mar","Mer","Jeu","Ven","Sam","Dim")) | U6: =IF(U5="","",CHOOSE(WEEKDAY(DATE('Paramètres'!$B$5,1,18),2),"Lun","Mar","Mer","Jeu","Ven","Sam","Dim")) | V6: =IF(V5="","",CHOOSE(WEEKDAY(DATE('Paramètres'!$B$5,1,19),2),"Lun","Mar","Mer","Jeu","Ven","Sam","Dim")) | W6: =IF(W5="","",CHOOSE(WEEKDAY(DATE('Paramètres'!$B$5,1,20),2),"Lun","Mar","Mer","Jeu","Ven","Sam","Dim")) | X6: =IF(X5="","",CHOOSE(WEEKDAY(DATE('Paramètres'!$B$5,1,21),2),"Lun","Mar","Mer","Jeu","Ven","Sam","Dim")) | Y6: =IF(Y5="","",CHOOSE(WEEKDAY(DATE('Paramètres'!$B$5,1,22),2),"Lun","Mar","Mer","Jeu","Ven","Sam","Dim")) | Z6: =IF(Z5="","",CHOOSE(WEEKDAY(DATE('Paramètres'!$B$5,1,23),2),"Lun","Mar","Mer","Jeu","Ven","Sam","Dim")) | AA6: =IF(AA5="","",CHOOSE(WEEKDAY(DATE('Paramètres'!$B$5,1,24),2),"Lun","Mar","Mer","Jeu","Ven","Sam","Dim")) | AB6: =IF(AB5="","",CHOOSE(WEEKDAY(DATE('Paramètres'!$B$5,1,25),2),"Lun","Mar","Mer","Jeu","Ven","Sam","Dim")) | AC6: =IF(AC5="","",CHOOSE(WEEKDAY(DATE('Paramètres'!$B$5,1,26),2),"Lun","Mar","Mer","Jeu","Ven","Sam","Dim")) | AD6: =IF(AD5="","",CHOOSE(WEEKDAY(DATE('Paramètres'!$B$5,1,27),2),"Lun","Mar","Mer","Jeu","Ven","Sam","Dim")) | AE6: =IF(AE5="","",CHOOSE(WEEKDAY(DATE('Paramètres'!$B$5,1,28),2),"Lun","Mar","Mer","Jeu","Ven","Sam","Dim")) | AF6: =IF(AF5="","",CHOOSE(WEEKDAY(DATE('Paramètres'!$B$5,1,29),2),"Lun","Mar","Mer","Jeu","Ven","Sam","Dim")) | AG6: =IF(AG5="","",CHOOSE(WEEKDAY(DATE('Paramètres'!$B$5,1,30),2),"Lun","Mar","Mer","Jeu","Ven","Sam","Dim")) | AH6: =IF(AH5="","",CHOOSE(WEEKDAY(DATE('Paramètres'!$B$5,1,31),2),"Lun","Mar","Mer","Jeu","Ven","Sam","Dim"))
A7: =IF('Employés'!B5="","",'Employés'!A5) | B7: =IF('Employés'!B5="","",'Employés'!B5) | C7: =IF('Employés'!C5="","",'Employés'!C5) | AI7: =IF($B7="","",COUNTIF(D7:AH7,"P")) | AJ7: =IF($B7="","",COUNTIF(D7:AH7,"R")) | AK7: =IF($B7="","",COUNTIF(D7:AH7,"A")) | AL7: =IF($B7="","",COUNTIF(D7:AH7,"C")) | AM7: =IF($B7="","",COUNTIF(D7:AH7,"M")) | AN7: =IF($B7="","",IF(AI7+AJ7+AK7+AM7=0,"",(AI7+AJ7)/(AI7+AJ7+AK7+AM7))) | AO7: =IF($B7="","",IF('Employés'!D5="","",(AI7+AJ7+AL7)*'Employés'!D5))
A8: =IF('Employés'!B6="","",'Employés'!A6) | B8: =IF('Employés'!B6="","",'Employés'!B6) | C8: =IF('Employés'!C6="","",'Employés'!C6) | AI8: =IF($B8="","",COUNTIF(D8:AH8,"P")) | AJ8: =IF($B8="","",COUNTIF(D8:AH8,"R")) | AK8: =IF($B8="","",COUNTIF(D8:AH8,"A")) | AL8: =IF($B8="","",COUNTIF(D8:AH8,"C")) | AM8: =IF($B8="","",COUNTIF(D8:AH8,"M")) | AN8: =IF($B8="","",IF(AI8+AJ8+AK8+AM8=0,"",(AI8+AJ8)/(AI8+AJ8+AK8+AM8))) | AO8: =IF($B8="","",IF('Employés'!D6="","",(AI8+AJ8+AL8)*'Employés'!D6))
A9: =IF('Employés'!B7="","",'Employés'!A7) | B9: =IF('Employés'!B7="","",'Employés'!B7) | C9: =IF('Employés'!C7="","",'Employés'!C7) | AI9: =IF($B9="","",COUNTIF(D9:AH9,"P")) | AJ9: =IF($B9="","",COUNTIF(D9:AH9,"R")) | AK9: =IF($B9="","",COUNTIF(D9:AH9,"A")) | AL9: =IF($B9="","",COUNTIF(D9:AH9,"C")) | AM9: =IF($B9="","",COUNTIF(D9:AH9,"M")) | AN9: =IF($B9="","",IF(AI9+AJ9+AK9+AM9=0,"",(AI9+AJ9)/(AI9+AJ9+AK9+AM9))) | AO9: =IF($B9="","",IF('Employés'!D7="","",(AI9+AJ9+AL9)*'Employés'!D7))
A10: =IF('Employés'!B8="","",'Employés'!A8) | B10: =IF('Employés'!B8="","",'Employés'!B8) | C10: =IF('Employés'!C8="","",'Employés'!C8) | AI10: =IF($B10="","",COUNTIF(D10:AH10,"P")) | AJ10: =IF($B10="","",COUNTIF(D10:AH10,"R")) | AK10: =IF($B10="","",COUNTIF(D10:AH10,"A")) | AL10: =IF($B10="","",COUNTIF(D10:AH10,"C")) | AM10: =IF($B10="","",COUNTIF(D10:AH10,"M")) | AN10: =IF($B10="","",IF(AI10+AJ10+AK10+AM10=0,"",(AI10+AJ10)/(AI10+AJ10+AK10+AM10))) | AO10: =IF($B10="","",IF('Employés'!D8="","",(AI10+AJ10+AL10)*'Employés'!D8))
A11: =IF('Employés'!B9="","",'Employés'!A9) | B11: =IF('Employés'!B9="","",'Employés'!B9) | C11: =IF('Employés'!C9="","",'Employés'!C9) | AI11: =IF($B11="","",COUNTIF(D11:AH11,"P")) | AJ11: =IF($B11="","",COUNTIF(D11:AH11,"R")) | AK11: =IF($B11="","",COUNTIF(D11:AH11,"A")) | AL11: =IF($B11="","",COUNTIF(D11:AH11,"C")) | AM11: =IF($B11="","",COUNTIF(D11:AH11,"M")) | AN11: =IF($B11="","",IF(AI11+AJ11+AK11+AM11=0,"",(AI11+AJ11)/(AI11+AJ11+AK11+AM11))) | AO11: =IF($B11="","",IF('Employés'!D9="","",(AI11+AJ11+AL11)*'Employés'!D9))
A12: =IF('Employés'!B10="","",'Employés'!A10) | B12: =IF('Employés'!B10="","",'Employés'!B10) | C12: =IF('Employés'!C10="","",'Employés'!C10) | AI12: =IF($B12="","",COUNTIF(D12:AH12,"P")) | AJ12: =IF($B12="","",COUNTIF(D12:AH12,"R")) | AK12: =IF($B12="","",COUNTIF(D12:AH12,"A")) | AL12: =IF($B12="","",COUNTIF(D12:AH12,"C")) | AM12: =IF($B12="","",COUNTIF(D12:AH12,"M")) | AN12: =IF($B12="","",IF(AI12+AJ12+AK12+AM12=0,"",(AI12+AJ12)/(AI12+AJ12+AK12+AM12))) | AO12: =IF($B12="","",IF('Employés'!D10="","",(AI12+AJ12+AL12)*'Employés'!D10))
A13: =IF('Employés'!B11="","",'Employés'!A11) | B13: =IF('Employés'!B11="","",'Employés'!B11) | C13: =IF('Employés'!C11="","",'Employés'!C11) | AI13: =IF($B13="","",COUNTIF(D13:AH13,"P")) | AJ13: =IF($B13="","",COUNTIF(D13:AH13,"R")) | AK13: =IF($B13="","",COUNTIF(D13:AH13,"A")) | AL13: =IF($B13="","",COUNTIF(D13:AH13,"C")) | AM13: =IF($B13="","",COUNTIF(D13:AH13,"M")) | AN13: =IF($B13="","",IF(AI13+AJ13+AK13+AM13=0,"",(AI13+AJ13)/(AI13+AJ13+AK13+AM13))) | AO13: =IF($B13="","",IF('Employés'!D11="","",(AI13+AJ13+AL13)*'Employés'!D11))
A14: =IF('Employés'!B12="","",'Employés'!A12) | B14: =IF('Employés'!B12="","",'Employés'!B12) | C14: =IF('Employés'!C12="","",'Employés'!C12) | AI14: =IF($B14="","",COUNTIF(D14:AH14,"P")) | AJ14: =IF($B14="","",COUNTIF(D14:AH14,"R")) | AK14: =IF($B14="","",COUNTIF(D14:AH14,"A")) | AL14: =IF($B14="","",COUNTIF(D14:AH14,"C")) | AM14: =IF($B14="","",COUNTIF(D14:AH14,"M")) | AN14: =IF($B14="","",IF(AI14+AJ14+AK14+AM14=0,"",(AI14+AJ14)/(AI14+AJ14+AK14+AM14))) | AO14: =IF($B14="","",IF('Employés'!D12="","",(AI14+AJ14+AL14)*'Employés'!D12))
A15: =IF('Employés'!B13="","",'Employés'!A13) | B15: =IF('Employés'!B13="","",'Employés'!B13) | C15: =IF('Employés'!C13="","",'Employés'!C13) | AI15: =IF($B15="","",COUNTIF(D15:AH15,"P")) | AJ15: =IF($B15="","",COUNTIF(D15:AH15,"R")) | AK15: =IF($B15="","",COUNTIF(D15:AH15,"A")) | AL15: =IF($B15="","",COUNTIF(D15:AH15,"C")) | AM15: =IF($B15="","",COUNTIF(D15:AH15,"M")) | AN15: =IF($B15="","",IF(AI15+AJ15+AK15+AM15=0,"",(AI15+AJ15)/(AI15+AJ15+AK15+AM15))) | AO15: =IF($B15="","",IF('Employés'!D13="","",(AI15+AJ15+AL15)*'Employés'!D13))
A16: =IF('Employés'!B14="","",'Employés'!A14) | B16: =IF('Employés'!B14="","",'Employés'!B14) | C16: =IF('Employés'!C14="","",'Employés'!C14) | AI16: =IF($B16="","",COUNTIF(D16:AH16,"P")) | AJ16: =IF($B16="","",COUNTIF(D16:AH16,"R")) | AK16: =IF($B16="","",COUNTIF(D16:AH16,"A")) | AL16: =IF($B16="","",COUNTIF(D16:AH16,"C")) | AM16: =IF($B16="","",COUNTIF(D16:AH16,"M")) | AN16: =IF($B16="","",IF(AI16+AJ16+AK16+AM16=0,"",(AI16+AJ16)/(AI16+AJ16+AK16+AM16))) | AO16: =IF($B16="","",IF('Employés'!D14="","",(AI16+AJ16+AL16)*'Employés'!D14))
A17: =IF('Employés'!B15="","",'Employés'!A15) | B17: =IF('Employés'!B15="","",'Employés'!B15) | C17: =IF('Employés'!C15="","",'Employés'!C15) | AI17: =IF($B17="","",COUNTIF(D17:AH17,"P")) | AJ17: =IF($B17="","",COUNTIF(D17:AH17,"R")) | AK17: =IF($B17="","",COUNTIF(D17:AH17,"A")) | AL17: =IF($B17="","",COUNTIF(D17:AH17,"C")) | AM17: =IF($B17="","",COUNTIF(D17:AH17,"M")) | AN17: =IF($B17="","",IF(AI17+AJ17+AK17+AM17=0,"",(AI17+AJ17)/(AI17+AJ17+AK17+AM17))) | AO17: =IF($B17="","",IF('Employés'!D15="","",(AI17+AJ17+AL17)*'Employés'!D15))
A18: =IF('Employés'!B16="","",'Employés'!A16) | B18: =IF('Employés'!B16="","",'Employés'!B16) | C18: =IF('Employés'!C16="","",'Employés'!C16) | AI18: =IF($B18="","",COUNTIF(D18:AH18,"P")) | AJ18: =IF($B18="","",COUNTIF(D18:AH18,"R")) | AK18: =IF($B18="","",COUNTIF(D18:AH18,"A")) | AL18: =IF($B18="","",COUNTIF(D18:AH18,"C")) | AM18: =IF($B18="","",COUNTIF(D18:AH18,"M")) | AN18: =IF($B18="","",IF(AI18+AJ18+AK18+AM18=0,"",(AI18+AJ18)/(AI18+AJ18+AK18+AM18))) | AO18: =IF($B18="","",IF('Employés'!D16="","",(AI18+AJ18+AL18)*'Employés'!D16))
... A36: =IF('Employés'!B34="","",'Employés'!A34) | B36: =IF('Employés'!B34="","",'Employés'!B34) | C36: =IF('Employés'!C34="","",'Employés'!C34) | AI36: =IF($B36="","",COUNTIF(D36:AH36,"P")) | AJ36: =IF($B36="","",COUNTIF(D36:AH36,"R")) | AK36: =IF($B36="","",COUNTIF(D36:AH36,"A")) | AL36: =IF($B36="","",COUNTIF(D36:AH36,"C")) | AM36: =IF($B36="","",COUNTIF(D36:AH36,"M")) | AN36: =IF($B36="","",IF(AI36+AJ36+AK36+AM36=0,"",(AI36+AJ36)/(AI36+AJ36+AK36+AM36))) | AO36: =IF($B36="","",IF('Employés'!D34="","",(AI36+AJ36+AL36)*'Employés'!D34))
B37: TOTAL | AI37: =SUM(AI7:AI36) | AJ37: =SUM(AJ7:AJ36) | AK37: =SUM(AK7:AK36) | AL37: =SUM(AL7:AL36) | AM37: =SUM(AM7:AM36) | AO37: =SUM(AO7:AO36)

Sheet Février
A1: ='Paramètres'!$B$4&" · Pointage de Février "&'Paramètres'!$B$5
A2: Outil offert par Logia (DWTS) · Un logiciel sur mesure pour votre entreprise ? WhatsApp 062 67 14 45
A3: Codes : | D3: P = Présent | I3: R = En retard | N3: A = Absent | S3: C = Congé | X3: M = Malade
A5: ID | B5: Nom | C5: Poste | D5: =IF(MONTH(DATE('Paramètres'!$B$5,2,1))=2,1,"") | E5: =IF(MONTH(DATE('Paramètres'!$B$5,2,2))=2,2,"") | F5: =IF(MONTH(DATE('Paramètres'!$B$5,2,3))=2,3,"") | G5: =IF(MONTH(DATE('Paramètres'!$B$5,2,4))=2,4,"") | H5: =IF(MONTH(DATE('Paramètres'!$B$5,2,5))=2,5,"") | I5: =IF(MONTH(DATE('Paramètres'!$B$5,2,6))=2,6,"") | J5: =IF(MONTH(DATE('Paramètres'!$B$5,2,7))=2,7,"") | K5: =IF(MONTH(DATE('Paramètres'!$B$5,2,8))=2,8,"") | L5: =IF(MONTH(DATE('Paramètres'!$B$5,2,9))=2,9,"") | M5: =IF(MONTH(DATE('Paramètres'!$B$5,2,10))=2,10,"") | N5: =IF(MONTH(DATE('Paramètres'!$B$5,2,11))=2,11,"") | O5: =IF(MONTH(DATE('Paramètres'!$B$5,2,12))=2,12,"") | P5: =IF(MONTH(DATE('Paramètres'!$B$5,2,13))=2,13,"") | Q5: =IF(MONTH(DATE('Paramètres'!$B$5,2,14))=2,14,"") | R5: =IF(MONTH(DATE('Paramètres'!$B$5,2,15))=2,15,"") | S5: =IF(MONTH(DATE('Paramètres'!$B$5,2,16))=2,16,"") | T5: =IF(MONTH(DATE('Paramètres'!$B$5,2,17))=2,17,"") | U5: =IF(MONTH(DATE('Paramètres'!$B$5,2,18))=2,18,"") | V5: =IF(MONTH(DATE('Paramètres'!$B$5,2,19))=2,19,"") | W5: =IF(MONTH(DATE('Paramètres'!$B$5,2,20))=2,20,"") | X5: =IF(MONTH(DATE('Paramètres'!$B$5,2,21))=2,21,"") | Y5: =IF(MONTH(DATE('Paramètres'!$B$5,2,22))=2,22,"") | Z5: =IF(MONTH(DATE('Paramètres'!$B$5,2,23))=2,23,"") | AA5: =IF(MONTH(DATE('Paramètres'!$B$5,2,24))=2,24,"") | AB5: =IF(MONTH(DATE('Paramètres'!$B$5,2,25))=2,25,"") | AC5: =IF(MONTH(DATE('Paramètres'!$B$5,2,26))=2,26,"") | AD5: =IF(MONTH(DATE('Paramètres'!$B$5,2,27))=2,27,"") | AE5: =IF(MONTH(DATE('Paramètres'!$B$5,2,28))=2,28,"") | AF5: =IF(MONTH(DATE('Paramètres'!$B$5,2,29))=2,29,"") | AG5: =IF(MONTH(DATE('Paramètres'!$B$5,2,30))=2,30,"") | AH5: =IF(MONTH(DATE('Paramètres'!$B$5,2,31))=2,31,"") | AI5: Présent | AJ5: Retard | AK5: Absent | AL5: Congé | AM5: Malade | AN5: Taux de présence | AO5: Salaire dû
D6: =IF(D5="","",CHOOSE(WEEKDAY(DATE('Paramètres'!$B$5,2,1),2),"Lun","Mar","Mer","Jeu","Ven","Sam","Dim")) | E6: =IF(E5="","",CHOOSE(WEEKDAY(DATE('Paramètres'!$B$5,2,2),2),"Lun","Mar","Mer","Jeu","Ven","Sam","Dim")) | F6: =IF(F5="","",CHOOSE(WEEKDAY(DATE('Paramètres'!$B$5,2,3),2),"Lun","Mar","Mer","Jeu","Ven","Sam","Dim")) | G6: =IF(G5="","",CHOOSE(WEEKDAY(DATE('Paramètres'!$B$5,2,4),2),"Lun","Mar","Mer","Jeu","Ven","Sam","Dim")) | H6: =IF(H5="","",CHOOSE(WEEKDAY(DATE('Paramètres'!$B$5,2,5),2),"Lun","Mar","Mer","Jeu","Ven","Sam","Dim")) | I6: =IF(I5="","",CHOOSE(WEEKDAY(DATE('Paramètres'!$B$5,2,6),2),"Lun","Mar","Mer","Jeu","Ven","Sam","Dim")) | J6: =IF(J5="","",CHOOSE(WEEKDAY(DATE('Paramètres'!$B$5,2,7),2),"Lun","Mar","Mer","Jeu","Ven","Sam","Dim")) | K6: =IF(K5="","",CHOOSE(WEEKDAY(DATE('Paramètres'!$B$5,2,8),2),"Lun","Mar","Mer","Jeu","Ven","Sam","Dim")) | L6: =IF(L5="","",CHOOSE(WEEKDAY(DATE('Paramètres'!$B$5,2,9),2),"Lun","Mar","Mer","Jeu","Ven","Sam","Dim")) | M6: =IF(M5="","",CHOOSE(WEEKDAY(DATE('Paramètres'!$B$5,2,10),2),"Lun","Mar","Mer","Jeu","Ven","Sam","Dim")) | N6: =IF(N5="","",CHOOSE(WEEKDAY(DATE('Paramètres'!$B$5,2,11),2),"Lun","Mar","Mer","Jeu","Ven","Sam","Dim")) | O6: =IF(O5="","",CHOOSE(WEEKDAY(DATE('Paramètres'!$B$5,2,12),2),"Lun","Mar","Mer","Jeu","Ven","Sam","Dim")) | P6: =IF(P5="","",CHOOSE(WEEKDAY(DATE('Paramètres'!$B$5,2,13),2),"Lun","Mar","Mer","Jeu","Ven","Sam","Dim")) | Q6: =IF(Q5="","",CHOOSE(WEEKDAY(DATE('Paramètres'!$B$5,2,14),2),"Lun","Mar","Mer","Jeu","Ven","Sam","Dim")) | R6: =IF(R5="","",CHOOSE(WEEKDAY(DATE('Paramètres'!$B$5,2,15),2),"Lun","Mar","Mer","Jeu","Ven","Sam","Dim")) | S6: =IF(S5="","",CHOOSE(WEEKDAY(DATE('Paramètres'!$B$5,2,16),2),"Lun","Mar","Mer","Jeu","Ven","Sam","Dim")) | T6: =IF(T5="","",CHOOSE(WEEKDAY(DATE('Paramètres'!$B$5,2,17),2),"Lun","Mar","Mer","Jeu","Ven","Sam","Dim")) | U6: =IF(U5="","",CHOOSE(WEEKDAY(DATE('Paramètres'!$B$5,2,18),2),"Lun","Mar","Mer","Jeu","Ven","Sam","Dim")) | V6: =IF(V5="","",CHOOSE(WEEKDAY(DATE('Paramètres'!$B$5,2,19),2),"Lun","Mar","Mer","Jeu","Ven","Sam","Dim")) | W6: =IF(W5="","",CHOOSE(WEEKDAY(DATE('Paramètres'!$B$5,2,20),2),"Lun","Mar","Mer","Jeu","Ven","Sam","Dim")) | X6: =IF(X5="","",CHOOSE(WEEKDAY(DATE('Paramètres'!$B$5,2,21),2),"Lun","Mar","Mer","Jeu","Ven","Sam","Dim")) | Y6: =IF(Y5="","",CHOOSE(WEEKDAY(DATE('Paramètres'!$B$5,2,22),2),"Lun","Mar","Mer","Jeu","Ven","Sam","Dim")) | Z6: =IF(Z5="","",CHOOSE(WEEKDAY(DATE('Paramètres'!$B$5,2,23),2),"Lun","Mar","Mer","Jeu","Ven","Sam","Dim")) | AA6: =IF(AA5="","",CHOOSE(WEEKDAY(DATE('Paramètres'!$B$5,2,24),2),"Lun","Mar","Mer","Jeu","Ven","Sam","Dim")) | AB6: =IF(AB5="","",CHOOSE(WEEKDAY(DATE('Paramètres'!$B$5,2,25),2),"Lun","Mar","Mer","Jeu","Ven","Sam","Dim")) | AC6: =IF(AC5="","",CHOOSE(WEEKDAY(DATE('Paramètres'!$B$5,2,26),2),"Lun","Mar","Mer","Jeu","Ven","Sam","Dim")) | AD6: =IF(AD5="","",CHOOSE(WEEKDAY(DATE('Paramètres'!$B$5,2,27),2),"Lun","Mar","Mer","Jeu","Ven","Sam","Dim")) | AE6: =IF(AE5="","",CHOOSE(WEEKDAY(DATE('Paramètres'!$B$5,2,28),2),"Lun","Mar","Mer","Jeu","Ven","Sam","Dim")) | AF6: =IF(AF5="","",CHOOSE(WEEKDAY(DATE('Paramètres'!$B$5,2,29),2),"Lun","Mar","Mer","Jeu","Ven","Sam","Dim")) | AG6: =IF(AG5="","",CHOOSE(WEEKDAY(DATE('Paramètres'!$B$5,2,30),2),"Lun","Mar","Mer","Jeu","Ven","Sam","Dim")) | AH6: =IF(AH5="","",CHOOSE(WEEKDAY(DATE('Paramètres'!$B$5,2,31),2),"Lun","Mar","Mer","Jeu","Ven","Sam","Dim"))
A7: =IF('Employés'!B5="","",'Employés'!A5) | B7: =IF('Employés'!B5="","",'Employés'!B5) | C7: =IF('Employés'!C5="","",'Employés'!C5) | AI7: =IF($B7="","",COUNTIF(D7:AH7,"P")) | AJ7: =IF($B7="","",COUNTIF(D7:AH7,"R")) | AK7: =IF($B7="","",COUNTIF(D7:AH7,"A")) | AL7: =IF($B7="","",COUNTIF(D7:AH7,"C")) | AM7: =IF($B7="","",COUNTIF(D7:AH7,"M")) | AN7: =IF($B7="","",IF(AI7+AJ7+AK7+AM7=0,"",(AI7+AJ7)/(AI7+AJ7+AK7+AM7))) | AO7: =IF($B7="","",IF('Employés'!D5="","",(AI7+AJ7+AL7)*'Employés'!D5))
A8: =IF('Employés'!B6="","",'Employés'!A6) | B8: =IF('Employés'!B6="","",'Employés'!B6) | C8: =IF('Employés'!C6="","",'Employés'!C6) | AI8: =IF($B8="","",COUNTIF(D8:AH8,"P")) | AJ8: =IF($B8="","",COUNTIF(D8:AH8,"R")) | AK8: =IF($B8="","",COUNTIF(D8:AH8,"A")) | AL8: =IF($B8="","",COUNTIF(D8:AH8,"C")) | AM8: =IF($B8="","",COUNTIF(D8:AH8,"M")) | AN8: =IF($B8="","",IF(AI8+AJ8+AK8+AM8=0,"",(AI8+AJ8)/(AI8+AJ8+AK8+AM8))) | AO8: =IF($B8="","",IF('Employés'!D6="","",(AI8+AJ8+AL8)*'Employés'!D6))
A9: =IF('Employés'!B7="","",'Employés'!A7) | B9: =IF('Employés'!B7="","",'Employés'!B7) | C9: =IF('Employés'!C7="","",'Employés'!C7) | AI9: =IF($B9="","",COUNTIF(D9:AH9,"P")) | AJ9: =IF($B9="","",COUNTIF(D9:AH9,"R")) | AK9: =IF($B9="","",COUNTIF(D9:AH9,"A")) | AL9: =IF($B9="","",COUNTIF(D9:AH9,"C")) | AM9: =IF($B9="","",COUNTIF(D9:AH9,"M")) | AN9: =IF($B9="","",IF(AI9+AJ9+AK9+AM9=0,"",(AI9+AJ9)/(AI9+AJ9+AK9+AM9))) | AO9: =IF($B9="","",IF('Employés'!D7="","",(AI9+AJ9+AL9)*'Employés'!D7))
A10: =IF('Employés'!B8="","",'Employés'!A8) | B10: =IF('Employés'!B8="","",'Employés'!B8) | C10: =IF('Employés'!C8="","",'Employés'!C8) | AI10: =IF($B10="","",COUNTIF(D10:AH10,"P")) | AJ10: =IF($B10="","",COUNTIF(D10:AH10,"R")) | AK10: =IF($B10="","",COUNTIF(D10:AH10,"A")) | AL10: =IF($B10="","",COUNTIF(D10:AH10,"C")) | AM10: =IF($B10="","",COUNTIF(D10:AH10,"M")) | AN10: =IF($B10="","",IF(AI10+AJ10+AK10+AM10=0,"",(AI10+AJ10)/(AI10+AJ10+AK10+AM10))) | AO10: =IF($B10="","",IF('Employés'!D8="","",(AI10+AJ10+AL10)*'Employés'!D8))
A11: =IF('Employés'!B9="","",'Employés'!A9) | B11: =IF('Employés'!B9="","",'Employés'!B9) | C11: =IF('Employés'!C9="","",'Employés'!C9) | AI11: =IF($B11="","",COUNTIF(D11:AH11,"P")) | AJ11: =IF($B11="","",COUNTIF(D11:AH11,"R")) | AK11: =IF($B11="","",COUNTIF(D11:AH11,"A")) | AL11: =IF($B11="","",COUNTIF(D11:AH11,"C")) | AM11: =IF($B11="","",COUNTIF(D11:AH11,"M")) | AN11: =IF($B11="","",IF(AI11+AJ11+AK11+AM11=0,"",(AI11+AJ11)/(AI11+AJ11+AK11+AM11))) | AO11: =IF($B11="","",IF('Employés'!D9="","",(AI11+AJ11+AL11)*'Employés'!D9))
A12: =IF('Employés'!B10="","",'Employés'!A10) | B12: =IF('Employés'!B10="","",'Employés'!B10) | C12: =IF('Employés'!C10="","",'Employés'!C10) | AI12: =IF($B12="","",COUNTIF(D12:AH12,"P")) | AJ12: =IF($B12="","",COUNTIF(D12:AH12,"R")) | AK12: =IF($B12="","",COUNTIF(D12:AH12,"A")) | AL12: =IF($B12="","",COUNTIF(D12:AH12,"C")) | AM12: =IF($B12="","",COUNTIF(D12:AH12,"M")) | AN12: =IF($B12="","",IF(AI12+AJ12+AK12+AM12=0,"",(AI12+AJ12)/(AI12+AJ12+AK12+AM12))) | AO12: =IF($B12="","",IF('Employés'!D10="","",(AI12+AJ12+AL12)*'Employés'!D10))
A13: =IF('Employés'!B11="","",'Employés'!A11) | B13: =IF('Employés'!B11="","",'Employés'!B11) | C13: =IF('Employés'!C11="","",'Employés'!C11) | AI13: =IF($B13="","",COUNTIF(D13:AH13,"P")) | AJ13: =IF($B13="","",COUNTIF(D13:AH13,"R")) | AK13: =IF($B13="","",COUNTIF(D13:AH13,"A")) | AL13: =IF($B13="","",COUNTIF(D13:AH13,"C")) | AM13: =IF($B13="","",COUNTIF(D13:AH13,"M")) | AN13: =IF($B13="","",IF(AI13+AJ13+AK13+AM13=0,"",(AI13+AJ13)/(AI13+AJ13+AK13+AM13))) | AO13: =IF($B13="","",IF('Employés'!D11="","",(AI13+AJ13+AL13)*'Employés'!D11))
A14: =IF('Employés'!B12="","",'Employés'!A12) | B14: =IF('Employés'!B12="","",'Employés'!B12) | C14: =IF('Employés'!C12="","",'Employés'!C12) | AI14: =IF($B14="","",COUNTIF(D14:AH14,"P")) | AJ14: =IF($B14="","",COUNTIF(D14:AH14,"R")) | AK14: =IF($B14="","",COUNTIF(D14:AH14,"A")) | AL14: =IF($B14="","",COUNTIF(D14:AH14,"C")) | AM14: =IF($B14="","",COUNTIF(D14:AH14,"M")) | AN14: =IF($B14="","",IF(AI14+AJ14+AK14+AM14=0,"",(AI14+AJ14)/(AI14+AJ14+AK14+AM14))) | AO14: =IF($B14="","",IF('Employés'!D12="","",(AI14+AJ14+AL14)*'Employés'!D12))
A15: =IF('Employés'!B13="","",'Employés'!A13) | B15: =IF('Employés'!B13="","",'Employés'!B13) | C15: =IF('Employés'!C13="","",'Employés'!C13) | AI15: =IF($B15="","",COUNTIF(D15:AH15,"P")) | AJ15: =IF($B15="","",COUNTIF(D15:AH15,"R")) | AK15: =IF($B15="","",COUNTIF(D15:AH15,"A")) | AL15: =IF($B15="","",COUNTIF(D15:AH15,"C")) | AM15: =IF($B15="","",COUNTIF(D15:AH15,"M")) | AN15: =IF($B15="","",IF(AI15+AJ15+AK15+AM15=0,"",(AI15+AJ15)/(AI15+AJ15+AK15+AM15))) | AO15: =IF($B15="","",IF('Employés'!D13="","",(AI15+AJ15+AL15)*'Employés'!D13))
A16: =IF('Employés'!B14="","",'Employés'!A14) | B16: =IF('Employés'!B14="","",'Employés'!B14) | C16: =IF('Employés'!C14="","",'Employés'!C14) | AI16: =IF($B16="","",COUNTIF(D16:AH16,"P")) | AJ16: =IF($B16="","",COUNTIF(D16:AH16,"R")) | AK16: =IF($B16="","",COUNTIF(D16:AH16,"A")) | AL16: =IF($B16="","",COUNTIF(D16:AH16,"C")) | AM16: =IF($B16="","",COUNTIF(D16:AH16,"M")) | AN16: =IF($B16="","",IF(AI16+AJ16+AK16+AM16=0,"",(AI16+AJ16)/(AI16+AJ16+AK16+AM16))) | AO16: =IF($B16="","",IF('Employés'!D14="","",(AI16+AJ16+AL16)*'Employés'!D14))
A17: =IF('Employés'!B15="","",'Employés'!A15) | B17: =IF('Employés'!B15="","",'Employés'!B15) | C17: =IF('Employés'!C15="","",'Employés'!C15) | AI17: =IF($B17="","",COUNTIF(D17:AH17,"P")) | AJ17: =IF($B17="","",COUNTIF(D17:AH17,"R")) | AK17: =IF($B17="","",COUNTIF(D17:AH17,"A")) | AL17: =IF($B17="","",COUNTIF(D17:AH17,"C")) | AM17: =IF($B17="","",COUNTIF(D17:AH17,"M")) | AN17: =IF($B17="","",IF(AI17+AJ17+AK17+AM17=0,"",(AI17+AJ17)/(AI17+AJ17+AK17+AM17))) | AO17: =IF($B17="","",IF('Employés'!D15="","",(AI17+AJ17+AL17)*'Employés'!D15))
A18: =IF('Employés'!B16="","",'Employés'!A16) | B18: =IF('Employés'!B16="","",'Employés'!B16) | C18: =IF('Employés'!C16="","",'Employés'!C16) | AI18: =IF($B18="","",COUNTIF(D18:AH18,"P")) | AJ18: =IF($B18="","",COUNTIF(D18:AH18,"R")) | AK18: =IF($B18="","",COUNTIF(D18:AH18,"A")) | AL18: =IF($B18="","",COUNTIF(D18:AH18,"C")) | AM18: =IF($B18="","",COUNTIF(D18:AH18,"M")) | AN18: =IF($B18="","",IF(AI18+AJ18+AK18+AM18=0,"",(AI18+AJ18)/(AI18+AJ18+AK18+AM18))) | AO18: =IF($B18="","",IF('Employés'!D16="","",(AI18+AJ18+AL18)*'Employés'!D16))
... A36: =IF('Employés'!B34="","",'Employés'!A34) | B36: =IF('Employés'!B34="","",'Employés'!B34) | C36: =IF('Employés'!C34="","",'Employés'!C34) | AI36: =IF($B36="","",COUNTIF(D36:AH36,"P")) | AJ36: =IF($B36="","",COUNTIF(D36:AH36,"R")) | AK36: =IF($B36="","",COUNTIF(D36:AH36,"A")) | AL36: =IF($B36="","",COUNTIF(D36:AH36,"C")) | AM36: =IF($B36="","",COUNTIF(D36:AH36,"M")) | AN36: =IF($B36="","",IF(AI36+AJ36+AK36+AM36=0,"",(AI36+AJ36)/(AI36+AJ36+AK36+AM36))) | AO36: =IF($B36="","",IF('Employés'!D34="","",(AI36+AJ36+AL36)*'Employés'!D34))
B37: TOTAL | AI37: =SUM(AI7:AI36) | AJ37: =SUM(AJ7:AJ36) | AK37: =SUM(AK7:AK36) | AL37: =SUM(AL7:AL36) | AM37: =SUM(AM7:AM36) | AO37: =SUM(AO7:AO36)

Sheet Mars
A1: ='Paramètres'!$B$4&" · Pointage de Mars "&'Paramètres'!$B$5
A2: Outil offert par Logia (DWTS) · Un logiciel sur mesure pour votre entreprise ? WhatsApp 062 67 14 45
A3: Codes : | D3: P = Présent | I3: R = En retard | N3: A = Absent | S3: C = Congé | X3: M = Malade
A5: ID | B5: Nom | C5: Poste | D5: =IF(MONTH(DATE('Paramètres'!$B$5,3,1))=3,1,"") | E5: =IF(MONTH(DATE('Paramètres'!$B$5,3,2))=3,2,"") | F5: =IF(MONTH(DATE('Paramètres'!$B$5,3,3))=3,3,"") | G5: =IF(MONTH(DATE('Paramètres'!$B$5,3,4))=3,4,"") | H5: =IF(MONTH(DATE('Paramètres'!$B$5,3,5))=3,5,"") | I5: =IF(MONTH(DATE('Paramètres'!$B$5,3,6))=3,6,"") | J5: =IF(MONTH(DATE('Paramètres'!$B$5,3,7))=3,7,"") | K5: =IF(MONTH(DATE('Paramètres'!$B$5,3,8))=3,8,"") | L5: =IF(MONTH(DATE('Paramètres'!$B$5,3,9))=3,9,"") | M5: =IF(MONTH(DATE('Paramètres'!$B$5,3,10))=3,10,"") | N5: =IF(MONTH(DATE('Paramètres'!$B$5,3,11))=3,11,"") | O5: =IF(MONTH(DATE('Paramètres'!$B$5,3,12))=3,12,"") | P5: =IF(MONTH(DATE('Paramètres'!$B$5,3,13))=3,13,"") | Q5: =IF(MONTH(DATE('Paramètres'!$B$5,3,14))=3,14,"") | R5: =IF(MONTH(DATE('Paramètres'!$B$5,3,15))=3,15,"") | S5: =IF(MONTH(DATE('Paramètres'!$B$5,3,16))=3,16,"") | T5: =IF(MONTH(DATE('Paramètres'!$B$5,3,17))=3,17,"") | U5: =IF(MONTH(DATE('Paramètres'!$B$5,3,18))=3,18,"") | V5: =IF(MONTH(DATE('Paramètres'!$B$5,3,19))=3,19,"") | W5: =IF(MONTH(DATE('Paramètres'!$B$5,3,20))=3,20,"") | X5: =IF(MONTH(DATE('Paramètres'!$B$5,3,21))=3,21,"") | Y5: =IF(MONTH(DATE('Paramètres'!$B$5,3,22))=3,22,"") | Z5: =IF(MONTH(DATE('Paramètres'!$B$5,3,23))=3,23,"") | AA5: =IF(MONTH(DATE('Paramètres'!$B$5,3,24))=3,24,"") | AB5: =IF(MONTH(DATE('Paramètres'!$B$5,3,25))=3,25,"") | AC5: =IF(MONTH(DATE('Paramètres'!$B$5,3,26))=3,26,"") | AD5: =IF(MONTH(DATE('Paramètres'!$B$5,3,27))=3,27,"") | AE5: =IF(MONTH(DATE('Paramètres'!$B$5,3,28))=3,28,"") | AF5: =IF(MONTH(DATE('Paramètres'!$B$5,3,29))=3,29,"") | AG5: =IF(MONTH(DATE('Paramètres'!$B$5,3,30))=3,30,"") | AH5: =IF(MONTH(DATE('Paramètres'!$B$5,3,31))=3,31,"") | AI5: Présent | AJ5: Retard | AK5: Absent | AL5: Congé | AM5: Malade | AN5: Taux de présence | AO5: Salaire dû
D6: =IF(D5="","",CHOOSE(WEEKDAY(DATE('Paramètres'!$B$5,3,1),2),"Lun","Mar","Mer","Jeu","Ven","Sam","Dim")) | E6: =IF(E5="","",CHOOSE(WEEKDAY(DATE('Paramètres'!$B$5,3,2),2),"Lun","Mar","Mer","Jeu","Ven","Sam","Dim")) | F6: =IF(F5="","",CHOOSE(WEEKDAY(DATE('Paramètres'!$B$5,3,3),2),"Lun","Mar","Mer","Jeu","Ven","Sam","Dim")) | G6: =IF(G5="","",CHOOSE(WEEKDAY(DATE('Paramètres'!$B$5,3,4),2),"Lun","Mar","Mer","Jeu","Ven","Sam","Dim")) | H6: =IF(H5="","",CHOOSE(WEEKDAY(DATE('Paramètres'!$B$5,3,5),2),"Lun","Mar","Mer","Jeu","Ven","Sam","Dim")) | I6: =IF(I5="","",CHOOSE(WEEKDAY(DATE('Paramètres'!$B$5,3,6),2),"Lun","Mar","Mer","Jeu","Ven","Sam","Dim")) | J6: =IF(J5="","",CHOOSE(WEEKDAY(DATE('Paramètres'!$B$5,3,7),2),"Lun","Mar","Mer","Jeu","Ven","Sam","Dim")) | K6: =IF(K5="","",CHOOSE(WEEKDAY(DATE('Paramètres'!$B$5,3,8),2),"Lun","Mar","Mer","Jeu","Ven","Sam","Dim")) | L6: =IF(L5="","",CHOOSE(WEEKDAY(DATE('Paramètres'!$B$5,3,9),2),"Lun","Mar","Mer","Jeu","Ven","Sam","Dim")) | M6: =IF(M5="","",CHOOSE(WEEKDAY(DATE('Paramètres'!$B$5,3,10),2),"Lun","Mar","Mer","Jeu","Ven","Sam","Dim")) | N6: =IF(N5="","",CHOOSE(WEEKDAY(DATE('Paramètres'!$B$5,3,11),2),"Lun","Mar","Mer","Jeu","Ven","Sam","Dim")) | O6: =IF(O5="","",CHOOSE(WEEKDAY(DATE('Paramètres'!$B$5,3,12),2),"Lun","Mar","Mer","Jeu","Ven","Sam","Dim")) | P6: =IF(P5="","",CHOOSE(WEEKDAY(DATE('Paramètres'!$B$5,3,13),2),"Lun","Mar","Mer","Jeu","Ven","Sam","Dim")) | Q6: =IF(Q5="","",CHOOSE(WEEKDAY(DATE('Paramètres'!$B$5,3,14),2),"Lun","Mar","Mer","Jeu","Ven","Sam","Dim")) | R6: =IF(R5="","",CHOOSE(WEEKDAY(DATE('Paramètres'!$B$5,3,15),2),"Lun","Mar","Mer","Jeu","Ven","Sam","Dim")) | S6: =IF(S5="","",CHOOSE(WEEKDAY(DATE('Paramètres'!$B$5,3,16),2),"Lun","Mar","Mer","Jeu","Ven","Sam","Dim")) | T6: =IF(T5="","",CHOOSE(WEEKDAY(DATE('Paramètres'!$B$5,3,17),2),"Lun","Mar","Mer","Jeu","Ven","Sam","Dim")) | U6: =IF(U5="","",CHOOSE(WEEKDAY(DATE('Paramètres'!$B$5,3,18),2),"Lun","Mar","Mer","Jeu","Ven","Sam","Dim")) | V6: =IF(V5="","",CHOOSE(WEEKDAY(DATE('Paramètres'!$B$5,3,19),2),"Lun","Mar","Mer","Jeu","Ven","Sam","Dim")) | W6: =IF(W5="","",CHOOSE(WEEKDAY(DATE('Paramètres'!$B$5,3,20),2),"Lun","Mar","Mer","Jeu","Ven","Sam","Dim")) | X6: =IF(X5="","",CHOOSE(WEEKDAY(DATE('Paramètres'!$B$5,3,21),2),"Lun","Mar","Mer","Jeu","Ven","Sam","Dim")) | Y6: =IF(Y5="","",CHOOSE(WEEKDAY(DATE('Paramètres'!$B$5,3,22),2),"Lun","Mar","Mer","Jeu","Ven","Sam","Dim")) | Z6: =IF(Z5="","",CHOOSE(WEEKDAY(DATE('Paramètres'!$B$5,3,23),2),"Lun","Mar","Mer","Jeu","Ven","Sam","Dim")) | AA6: =IF(AA5="","",CHOOSE(WEEKDAY(DATE('Paramètres'!$B$5,3,24),2),"Lun","Mar","Mer","Jeu","Ven","Sam","Dim")) | AB6: =IF(AB5="","",CHOOSE(WEEKDAY(DATE('Paramètres'!$B$5,3,25),2),"Lun","Mar","Mer","Jeu","Ven","Sam","Dim")) | AC6: =IF(AC5="","",CHOOSE(WEEKDAY(DATE('Paramètres'!$B$5,3,26),2),"Lun","Mar","Mer","Jeu","Ven","Sam","Dim")) | AD6: =IF(AD5="","",CHOOSE(WEEKDAY(DATE('Paramètres'!$B$5,3,27),2),"Lun","Mar","Mer","Jeu","Ven","Sam","Dim")) | AE6: =IF(AE5="","",CHOOSE(WEEKDAY(DATE('Paramètres'!$B$5,3,28),2),"Lun","Mar","Mer","Jeu","Ven","Sam","Dim")) | AF6: =IF(AF5="","",CHOOSE(WEEKDAY(DATE('Paramètres'!$B$5,3,29),2),"Lun","Mar","Mer","Jeu","Ven","Sam","Dim")) | AG6: =IF(AG5="","",CHOOSE(WEEKDAY(DATE('Paramètres'!$B$5,3,30),2),"Lun","Mar","Mer","Jeu","Ven","Sam","Dim")) | AH6: =IF(AH5="","",CHOOSE(WEEKDAY(DATE('Paramètres'!$B$5,3,31),2),"Lun","Mar","Mer","Jeu","Ven","Sam","Dim"))
A7: =IF('Employés'!B5="","",'Employés'!A5) | B7: =IF('Employés'!B5="","",'Employés'!B5) | C7: =IF('Employés'!C5="","",'Employés'!C5) | AI7: =IF($B7="","",COUNTIF(D7:AH7,"P")) | AJ7: =IF($B7="","",COUNTIF(D7:AH7,"R")) | AK7: =IF($B7="","",COUNTIF(D7:AH7,"A")) | AL7: =IF($B7="","",COUNTIF(D7:AH7,"C")) | AM7: =IF($B7="","",COUNTIF(D7:AH7,"M")) | AN7: =IF($B7="","",IF(AI7+AJ7+AK7+AM7=0,"",(AI7+AJ7)/(AI7+AJ7+AK7+AM7))) | AO7: =IF($B7="","",IF('Employés'!D5="","",(AI7+AJ7+AL7)*'Employés'!D5))
A8: =IF('Employés'!B6="","",'Employés'!A6) | B8: =IF('Employés'!B6="","",'Employés'!B6) | C8: =IF('Employés'!C6="","",'Employés'!C6) | AI8: =IF($B8="","",COUNTIF(D8:AH8,"P")) | AJ8: =IF($B8="","",COUNTIF(D8:AH8,"R")) | AK8: =IF($B8="","",COUNTIF(D8:AH8,"A")) | AL8: =IF($B8="","",COUNTIF(D8:AH8,"C")) | AM8: =IF($B8="","",COUNTIF(D8:AH8,"M")) | AN8: =IF($B8="","",IF(AI8+AJ8+AK8+AM8=0,"",(AI8+AJ8)/(AI8+AJ8+AK8+AM8))) | AO8: =IF($B8="","",IF('Employés'!D6="","",(AI8+AJ8+AL8)*'Employés'!D6))
A9: =IF('Employés'!B7="","",'Employés'!A7) | B9: =IF('Employés'!B7="","",'Employés'!B7) | C9: =IF('Employés'!C7="","",'Employés'!C7) | AI9: =IF($B9="","",COUNTIF(D9:AH9,"P")) | AJ9: =IF($B9="","",COUNTIF(D9:AH9,"R")) | AK9: =IF($B9="","",COUNTIF(D9:AH9,"A")) | AL9: =IF($B9="","",COUNTIF(D9:AH9,"C")) | AM9: =IF($B9="","",COUNTIF(D9:AH9,"M")) | AN9: =IF($B9="","",IF(AI9+AJ9+AK9+AM9=0,"",(AI9+AJ9)/(AI9+AJ9+AK9+AM9))) | AO9: =IF($B9="","",IF('Employés'!D7="","",(AI9+AJ9+AL9)*'Employés'!D7))
A10: =IF('Employés'!B8="","",'Employés'!A8) | B10: =IF('Employés'!B8="","",'Employés'!B8) | C10: =IF('Employés'!C8="","",'Employés'!C8) | AI10: =IF($B10="","",COUNTIF(D10:AH10,"P")) | AJ10: =IF($B10="","",COUNTIF(D10:AH10,"R")) | AK10: =IF($B10="","",COUNTIF(D10:AH10,"A")) | AL10: =IF($B10="","",COUNTIF(D10:AH10,"C")) | AM10: =IF($B10="","",COUNTIF(D10:AH10,"M")) | AN10: =IF($B10="","",IF(AI10+AJ10+AK10+AM10=0,"",(AI10+AJ10)/(AI10+AJ10+AK10+AM10))) | AO10: =IF($B10="","",IF('Employés'!D8="","",(AI10+AJ10+AL10)*'Employés'!D8))
A11: =IF('Employés'!B9="","",'Employés'!A9) | B11: =IF('Employés'!B9="","",'Employés'!B9) | C11: =IF('Employés'!C9="","",'Employés'!C9) | AI11: =IF($B11="","",COUNTIF(D11:AH11,"P")) | AJ11: =IF($B11="","",COUNTIF(D11:AH11,"R")) | AK11: =IF($B11="","",COUNTIF(D11:AH11,"A")) | AL11: =IF($B11="","",COUNTIF(D11:AH11,"C")) | AM11: =IF($B11="","",COUNTIF(D11:AH11,"M")) | AN11: =IF($B11="","",IF(AI11+AJ11+AK11+AM11=0,"",(AI11+AJ11)/(AI11+AJ11+AK11+AM11))) | AO11: =IF($B11="","",IF('Employés'!D9="","",(AI11+AJ11+AL11)*'Employés'!D9))
A12: =IF('Employés'!B10="","",'Employés'!A10) | B12: =IF('Employés'!B10="","",'Employés'!B10) | C12: =IF('Employés'!C10="","",'Employés'!C10) | AI12: =IF($B12="","",COUNTIF(D12:AH12,"P")) | AJ12: =IF($B12="","",COUNTIF(D12:AH12,"R")) | AK12: =IF($B12="","",COUNTIF(D12:AH12,"A")) | AL12: =IF($B12="","",COUNTIF(D12:AH12,"C")) | AM12: =IF($B12="","",COUNTIF(D12:AH12,"M")) | AN12: =IF($B12="","",IF(AI12+AJ12+AK12+AM12=0,"",(AI12+AJ12)/(AI12+AJ12+AK12+AM12))) | AO12: =IF($B12="","",IF('Employés'!D10="","",(AI12+AJ12+AL12)*'Employés'!D10))
A13: =IF('Employés'!B11="","",'Employés'!A11) | B13: =IF('Employés'!B11="","",'Employés'!B11) | C13: =IF('Employés'!C11="","",'Employés'!C11) | AI13: =IF($B13="","",COUNTIF(D13:AH13,"P")) | AJ13: =IF($B13="","",COUNTIF(D13:AH13,"R")) | AK13: =IF($B13="","",COUNTIF(D13:AH13,"A")) | AL13: =IF($B13="","",COUNTIF(D13:AH13,"C")) | AM13: =IF($B13="","",COUNTIF(D13:AH13,"M")) | AN13: =IF($B13="","",IF(AI13+AJ13+AK13+AM13=0,"",(AI13+AJ13)/(AI13+AJ13+AK13+AM13))) | AO13: =IF($B13="","",IF('Employés'!D11="","",(AI13+AJ13+AL13)*'Employés'!D11))
A14: =IF('Employés'!B12="","",'Employés'!A12) | B14: =IF('Employés'!B12="","",'Employés'!B12) | C14: =IF('Employés'!C12="","",'Employés'!C12) | AI14: =IF($B14="","",COUNTIF(D14:AH14,"P")) | AJ14: =IF($B14="","",COUNTIF(D14:AH14,"R")) | AK14: =IF($B14="","",COUNTIF(D14:AH14,"A")) | AL14: =IF($B14="","",COUNTIF(D14:AH14,"C")) | AM14: =IF($B14="","",COUNTIF(D14:AH14,"M")) | AN14: =IF($B14="","",IF(AI14+AJ14+AK14+AM14=0,"",(AI14+AJ14)/(AI14+AJ14+AK14+AM14))) | AO14: =IF($B14="","",IF('Employés'!D12="","",(AI14+AJ14+AL14)*'Employés'!D12))
A15: =IF('Employés'!B13="","",'Employés'!A13) | B15: =IF('Employés'!B13="","",'Employés'!B13) | C15: =IF('Employés'!C13="","",'Employés'!C13) | AI15: =IF($B15="","",COUNTIF(D15:AH15,"P")) | AJ15: =IF($B15="","",COUNTIF(D15:AH15,"R")) | AK15: =IF($B15="","",COUNTIF(D15:AH15,"A")) | AL15: =IF($B15="","",COUNTIF(D15:AH15,"C")) | AM15: =IF($B15="","",COUNTIF(D15:AH15,"M")) | AN15: =IF($B15="","",IF(AI15+AJ15+AK15+AM15=0,"",(AI15+AJ15)/(AI15+AJ15+AK15+AM15))) | AO15: =IF($B15="","",IF('Employés'!D13="","",(AI15+AJ15+AL15)*'Employés'!D13))
A16: =IF('Employés'!B14="","",'Employés'!A14) | B16: =IF('Employés'!B14="","",'Employés'!B14) | C16: =IF('Employés'!C14="","",'Employés'!C14) | AI16: =IF($B16="","",COUNTIF(D16:AH16,"P")) | AJ16: =IF($B16="","",COUNTIF(D16:AH16,"R")) | AK16: =IF($B16="","",COUNTIF(D16:AH16,"A")) | AL16: =IF($B16="","",COUNTIF(D16:AH16,"C")) | AM16: =IF($B16="","",COUNTIF(D16:AH16,"M")) | AN16: =IF($B16="","",IF(AI16+AJ16+AK16+AM16=0,"",(AI16+AJ16)/(AI16+AJ16+AK16+AM16))) | AO16: =IF($B16="","",IF('Employés'!D14="","",(AI16+AJ16+AL16)*'Employés'!D14))
A17: =IF('Employés'!B15="","",'Employés'!A15) | B17: =IF('Employés'!B15="","",'Employés'!B15) | C17: =IF('Employés'!C15="","",'Employés'!C15) | AI17: =IF($B17="","",COUNTIF(D17:AH17,"P")) | AJ17: =IF($B17="","",COUNTIF(D17:AH17,"R")) | AK17: =IF($B17="","",COUNTIF(D17:AH17,"A")) | AL17: =IF($B17="","",COUNTIF(D17:AH17,"C")) | AM17: =IF($B17="","",COUNTIF(D17:AH17,"M")) | AN17: =IF($B17="","",IF(AI17+AJ17+AK17+AM17=0,"",(AI17+AJ17)/(AI17+AJ17+AK17+AM17))) | AO17: =IF($B17="","",IF('Employés'!D15="","",(AI17+AJ17+AL17)*'Employés'!D15))
A18: =IF('Employés'!B16="","",'Employés'!A16) | B18: =IF('Employés'!B16="","",'Employés'!B16) | C18: =IF('Employés'!C16="","",'Employés'!C16) | AI18: =IF($B18="","",COUNTIF(D18:AH18,"P")) | AJ18: =IF($B18="","",COUNTIF(D18:AH18,"R")) | AK18: =IF($B18="","",COUNTIF(D18:AH18,"A")) | AL18: =IF($B18="","",COUNTIF(D18:AH18,"C")) | AM18: =IF($B18="","",COUNTIF(D18:AH18,"M")) | AN18: =IF($B18="","",IF(AI18+AJ18+AK18+AM18=0,"",(AI18+AJ18)/(AI18+AJ18+AK18+AM18))) | AO18: =IF($B18="","",IF('Employés'!D16="","",(AI18+AJ18+AL18)*'Employés'!D16))
... A36: =IF('Employés'!B34="","",'Employés'!A34) | B36: =IF('Employés'!B34="","",'Employés'!B34) | C36: =IF('Employés'!C34="","",'Employés'!C34) | AI36: =IF($B36="","",COUNTIF(D36:AH36,"P")) | AJ36: =IF($B36="","",COUNTIF(D36:AH36,"R")) | AK36: =IF($B36="","",COUNTIF(D36:AH36,"A")) | AL36: =IF($B36="","",COUNTIF(D36:AH36,"C")) | AM36: =IF($B36="","",COUNTIF(D36:AH36,"M")) | AN36: =IF($B36="","",IF(AI36+AJ36+AK36+AM36=0,"",(AI36+AJ36)/(AI36+AJ36+AK36+AM36))) | AO36: =IF($B36="","",IF('Employés'!D34="","",(AI36+AJ36+AL36)*'Employés'!D34))
B37: TOTAL | AI37: =SUM(AI7:AI36) | AJ37: =SUM(AJ7:AJ36) | AK37: =SUM(AK7:AK36) | AL37: =SUM(AL7:AL36) | AM37: =SUM(AM7:AM36) | AO37: =SUM(AO7:AO36)

Sheet Avril
A1: ='Paramètres'!$B$4&" · Pointage de Avril "&'Paramètres'!$B$5
A2: Outil offert par Logia (DWTS) · Un logiciel sur mesure pour votre entreprise ? WhatsApp 062 67 14 45
A3: Codes : | D3: P = Présent | I3: R = En retard | N3: A = Absent | S3: C = Congé | X3: M = Malade
